Workbook

Sheet Sheet1
A1: STT | B1: MA_KHANG | C1: TEN_KHANG | D1: DCHI_KHANG | E1: MA_SOGCS | F1: DANH SỐ | G1: THANG | H1: TIỀN NỢ | I1: DTHOAI_DVU | J1: SO_TBI | K1: GHI CHU | L1: NHÓM | M1: ID_HDON | O1: MA_DVIQLY | P1: ID_HDON | Q1: MA_KHANG | R1: MA_KHTT | S1: TEN_KHANG | T1: TEN_KHTT | U1: DCHI_KHANG | V1: DCHI_KHTT | W1: LOAI_KHANG | X1: MANHOM_KHANG | Y1: NAM | Z1: THANG | AA1: KY | AB1: TIEN_PSINH | AC1: THUE_PSINH | AD1: TIEN_VC | AE1: THUE_VC | AF1: MA_PTTT | AG1: MA_TO | AH1: MA_SOGCS | AI1: MA_KVUC | AJ1: STT_TRANG | AK1: STT | AL1: TTHAI_NO_HTAI | AM1: TTRANG_SSAI | AN1: TTHAI_GIAO | AO1: LAN_GIAO | AP1: HTHUC_TTOAN | AQ1: LOAI_TBAO | AR1: CHUYEN_DVQLY | AS1: NGAY_PHANH | AT1: SO_SERY | AU1: KIHIEU_SERY | AV1: MA_DVU_TTOAN | AW1: ID_SORT | AX1: DTHOAI_DVU | AY1: SO_TBI | AZ1: THANG NO | BA1: TIEN NO | BB1: GHI CHU
A2: =SUBTOTAL(103,$L$2:L2) -> 1 | B2: PB15020064186 | C2: BAN QUẢN LÝ DỰ ÁN ĐẦU TƯ XÂY DỰNG KHU VỰC BÀ RỊA (ĐĐ Trần Đại Nghĩa) | D2: ĐĐ Trần Đại Nghĩa & MN Kim Dinh, Phường Long Hương, Thành phố Hồ Chí Minh, Việt Nam | E2: B1BDTD1ZA | F2: -21586 | G2: 6 | H2: 1622754 | I2: 0846313484 | J2: 09N20202014017230 | L2: Phạm Trần thanh Tâm | M2: 1596860052 | N2: =IF(COUNTIF($B$2:B2,B2)=1,1,0) -> 1 | O2: PE1800 | P2: 1596860052 | Q2: PB15020064186 | R2: PB15020012733 | S2: BAN QUẢN LÝ DỰ ÁN ĐẦU TƯ XÂY DỰNG KHU VỰC BÀ RỊA (ĐĐ Trần Đại Nghĩa) | T2: BAN QUẢN LÝ DỰ ÁN ĐẦU TƯ XÂY DỰNG KHU VỰC BÀ RỊA (Đ.Cổng Chào Bà Rịa) | U2: ĐĐ Trần Đại Nghĩa & MN Kim Dinh, Phường Long Hương, Thành phố Hồ Chí Minh, Việt Nam | V2: Số 138 Đường 27/4 Phường Bà Rịa, thành phố Hồ Chí Minh | W2: 1 | X2: HC03 | Y2: 2026 | Z2: 6 | AA2: 1 | AB2: 1502550 | AC2: 120204 | AD2: 0 | AE2: 0 | AF2: TM | AG2: null | AH2: B1BDTD1ZA | AJ2: 0 | AK2: 021586 | AL2: 0 | AM2: 0 | AN2: 0 | AO2: 0 | AP2: QN | AQ2: 0 | AR2: 0 | AS2: 02/07/26 | AT2: 1555096 | AU2: K26TDA | AV2: 0 | AW2: 3854 | AX2: 0846313484 | AY2: 09N20202014017230 | AZ2: 1-6/2026 | BA2: 1622754 | BB2: CON NO | BC2: =RIGHT(AK2,5) -> 21586 | BD2: =AI2&"-"&BC2 -> -21586
A3: =SUBTOTAL(103,$L$2:L3) -> 2 | B3: PB15020064186 | C3: BAN QUẢN LÝ DỰ ÁN ĐẦU TƯ XÂY DỰNG KHU VỰC BÀ RỊA (ĐĐ Trần Đại Nghĩa) | D3: ĐĐ Trần Đại Nghĩa & MN Kim Dinh, Phường Long Hương, Thành phố Hồ Chí Minh, Việt Nam | E3: B1BDTD1ZA | F3: -21586 | G3: 7 | H3: 1771807 | I3: 0846313484 | J3: 09N20202014017230 | L3: Phạm Trần thanh Tâm | M3: 1599800300 | N3: =IF(COUNTIF($B$2:B3,B3)=1,1,0) -> 0 | O3: PE1800 | P3: 1599800300 | Q3: PB15020064186 | R3: PB15020012733 | S3: BAN QUẢN LÝ DỰ ÁN ĐẦU TƯ XÂY DỰNG KHU VỰC BÀ RỊA (ĐĐ Trần Đại Nghĩa) | T3: TRUNG TÂM QUẢN LÝ GIAO THÔNG VÀ HẠ TẦNG KỸ THUẬT THÀNH PHỐ HỒ CHÍ MINH | U3: ĐĐ Trần Đại Nghĩa & MN Kim Dinh, Phường Long Hương, Thành phố Hồ Chí Minh, Việt Nam | V3: Số 360 đường Võ Nguyên Giáp, phường Phước Long, Thành phố Hồ Chí Minh, Việt Nam. | W3: 1 | X3: HC03 | Y3: 2026 | Z3: 7 | AA3: 1 | AB3: 1640562 | AC3: 131245 | AD3: 0 | AE3: 0 | AF3: TM | AG3: null | AH3: B1BDTD1ZA | AJ3: 0 | AK3: 021586 | AL3: 0 | AM3: 0 | AN3: 0 | AO3: 0 | AP3: QN | AQ3: 0 | AR3: 0 | AS3: 02/08/26 | AT3: 1792446 | AU3: K26TDA | AV3: 0 | AW3: 5857 | AX3: 0846313484 | AY3: 09N20202014017230 | AZ3: 1-7/2026 | BA3: 1771807 | BB3: CON NO | BC3: =RIGHT(AK3,5) -> 21586 | BD3: =AI3&"-"&BC3 -> -21586
A4: =SUBTOTAL(103,$L$2:L4) -> 3 | B4: PB15020079378 | C4: Lê Thị Võ | D4: 104 Hai Bà Trưng , Phường Bà Rịa, Thành phố Hồ Chí Minh | E4: B1BDCA4ZA | F4: -19070 | G4: 8 | H4: 4418600 | I4: 0972773839 | J4: 0 | K4: C | L4: Đỗ Hiếu Lễ | M4: 1555553559 | N4: =IF(COUNTIF($B$2:B4,B4)=1,1,0) -> 1 | O4: PE1800 | P4: 1555553559 | Q4: PB15020079378 | R4: PB15020079378 | S4: Lê Thị Võ | T4: Lê Thị Võ | U4: 104 Hai Bà Trưng , Phường Bà Rịa, Thành phố Hồ Chí Minh | V4: 104 Hai Bà Trưng Phường Bà Rịa, Thành phố Hồ Chí Minh | W4: 1 | X4: KHBT | Y4: 2025 | Z4: 8 | AA4: 1 | AB4: 4091296 | AC4: 327304 | AD4: 0 | AE4: 0 | AF4: TM | AG4: 01 | AH4: B1BDCA4ZA | AJ4: 0 | AK4: 19070 | AL4: 1 | AM4: 0 | AN4: 0 | AO4: 0 | AP4: NH | AQ4: 0 | AR4: 0 | AS4: 04/09/25 | AT4: 1157771 | AU4: K25TDA | AV4: 0 | AW4: 169 | AX4: 0972773839 | AZ4: 1-8/2025 | BA4: 4418600 | BB4: CON NO | BC4: =RIGHT(AK4,5) -> 19070 | BD4: =AI4&"-"&BC4 -> -19070
A5: =SUBTOTAL(103,$L$2:L5) -> 4 | B5: PE18000000285 | C5: VŨ TIẾN LƯƠNG | D5: Đường Phan Văn Trị, KP Kim Sơn, phường Long Hương, thành phố Hồ Chí Minh | E5: B1BACA2ZA | F5: -16315 | G5: 7 | H5: 2056417 | I5: 0357531747 | J5: 47M202525415303 | L5: Nguyễn Ngọc Kỳ | M5: 1601131296 | N5: =IF(COUNTIF($B$2:B5,B5)=1,1,0) -> 1 | O5: PE1800 | P5: 1601131296 | Q5: PE18000000285 | R5: PE18000000285 | S5: VŨ TIẾN LƯƠNG | T5: VŨ TIẾN LƯƠNG | U5: Đường Phan Văn Trị, KP Kim Sơn, phường Long Hương, thành phố Hồ Chí Minh | V5: Đường Phan Văn Trị, KP Kim Sơn, phường Long Hương, thành phố Hồ Chí Minh | W5: 1 | X5: SXCN | Y5: 2026 | Z5: 7 | AA5: 1 | AB5: 1904090 | AC5: 152327 | AD5: 0 | AE5: 0 | AF5: DT | AG5: PB1502 | AH5: B1BACA2ZA | AJ5: 0 | AK5: 016315 | AL5: 0 | AM5: 0 | AN5: 0 | AO5: 0 | AP5: NH | AQ5: 0 | AR5: 0 | AS5: 02/08/26 | AT5: 1784716 | AU5: K26TDA | AV5: 0 | AW5: 20434 | AX5: 0357531747 | AY5: 47M202525415303 | AZ5: 1-7/2026 | BA5: 2056417 | BB5: CON NO | BC5: =RIGHT(AK5,5) -> 16315 | BD5: =AI5&"-"&BC5 -> -16315
A6: =SUBTOTAL(103,$L$2:L6) -> 5 | B6: PB15020063459 | C6: Chu Anh Khoa | D6: Tổ 14, Kp. Hương Điền, Phường Long Hương, Thành phố Hồ Chí Minh | E6: B1BCLA3ZA | F6: -15620 | G6: 8 | H6: 160272 | I6: 0 | J6: 0 | L6: Nguyễn Ngọc Kỳ | M6: 1551577353 | N6: =IF(COUNTIF($B$2:B6,B6)=1,1,0) -> 1 | O6: PE1800 | P6: 1551577353 | Q6: PB15020063459 | R6: PB15020063459 | S6: Chu Anh Khoa | T6: Chu Anh Khoa | U6: Tổ 14, Kp. Hương Điền, Phường Long Hương, Thành phố Hồ Chí Minh | V6: Tổ 14, Kp. Hương Điền, P. Long Hương, TP.BR | W6: 0 | X6: KHBT | Y6: 2025 | Z6: 8 | AA6: 1 | AB6: 148400 | AC6: 11872 | AD6: 0 | AE6: 0 | AF6: UC | AG6: 01 | AH6: B1BCLA3ZA | AJ6: 0 | AK6: 15620 | AL6: 1 | AM6: 0 | AN6: 0 | AO6: 0 | AP6: NH | AQ6: 0 | AR6: 0 | AS6: 02/09/25 | AT6: 975397 | AU6: K25TDA | AV6: 0 | AW6: 97 | AZ6: 1-8/2025 | BA6: 160272 | BB6: CON NO | BC6: =RIGHT(AK6,5) -> 15620 | BD6: =AI6&"-"&BC6 -> -15620
A7: =SUBTOTAL(103,$L$2:L7) -> 6 | B7: PB15020050471 | C7: Nguyễn Văn Hoa | D7: Lê Hữu Trác - Long Tâm, Phường Bà Rịa, Thành phố Hồ Chí Minh | E7: B1BIYA1ZA | F7: -12350 | G7: 7 | H7: 1855505 | I7: 0589145561 | J7: T0320161611679602 | L7: Đỗ Thị Diễm Trang | M7: 1548999464 | N7: =IF(COUNTIF($B$2:B7,B7)=1,1,0) -> 1 | O7: PE1800 | P7: 1548999464 | Q7: PB15020050471 | R7: PB15020050471 | S7: Nguyễn Văn Hoa | T7: Nguyễn Văn Hoa | U7: Lê Hữu Trác - Long Tâm, Phường Bà Rịa, Thành phố Hồ Chí Minh | V7: Lê Hữu Trác - Long Tâm | W7: 0 | X7: KHBT | Y7: 2025 | Z7: 7 | AA7: 1 | AB7: 1718060 | AC7: 137445 | AD7: 0 | AE7: 0 | AF7: BL | AG7: PB1502 | AH7: B1BIYA1ZA | AJ7: 0 | AK7: 12350 | AL7: 1 | AM7: 0 | AN7: 0 | AO7: 0 | AP7: BL | AQ7: 0 | AR7: 0 | AS7: 02/08/25 | AT7: 791872 | AU7: K25TDA | AV7: 0 | AW7: 26 | AX7: 0589145561 | AY7: T0320161611679602 | AZ7: 1-7/2025 | BA7: 1855505 | BB7: CON NO | BC7: =RIGHT(AK7,5) -> 12350 | BD7: =AI7&"-"&BC7 -> -12350
A8: =SUBTOTAL(103,$L$2:L8) -> 7 | B8: PB15020050471 | C8: Nguyễn Văn Hoa | D8: Lê Hữu Trác - Long Tâm, Phường Bà Rịa, Thành phố Hồ Chí Minh | E8: B1BIYA1ZA | F8: -12350 | G8: 8 | H8: 366919 | I8: 0589145561 | J8: T0320161611679602 | L8: Đỗ Thị Diễm Trang | M8: 1552239320 | N8: =IF(COUNTIF($B$2:B8,B8)=1,1,0) -> 0 | O8: PE1800 | P8: 1552239320 | Q8: PB15020050471 | R8: PB15020050471 | S8: Nguyễn Văn Hoa | T8: Nguyễn Văn Hoa | U8: Lê Hữu Trác - Long Tâm, Phường Bà Rịa, Thành phố Hồ Chí Minh | V8: Lê Hữu Trác - Long Tâm | W8: 0 | X8: KHBT | Y8: 2025 | Z8: 8 | AA8: 1 | AB8: 339740 | AC8: 27179 | AD8: 0 | AE8: 0 | AF8: BL | AG8: PB1502 | AH8: B1BIYA1ZA | AJ8: 0 | AK8: 12350 | AL8: 1 | AM8: 0 | AN8: 0 | AO8: 0 | AP8: BL | AQ8: 0 | AR8: 0 | AS8: 02/09/25 | AT8: 976423 | AU8: K25TDA | AV8: 0 | AW8: 102 | AX8: 0589145561 | AY8: T0320161611679602 | AZ8: 1-8/2025 | BA8: 366919 | BB8: CON NO | BC8: =RIGHT(AK8,5) -> 12350 | BD8: =AI8&"-"&BC8 -> -12350
A9: =SUBTOTAL(103,$L$2:L9) -> 8 | B9: PB15020070605 | C9: Trần Thúy Ngân | D9: Tổ 13, Hương Điền, Phường Long Hương, Thành phố Hồ Chí Minh | E9: B1BCNA1ZA | F9: -10500 | G9: 8 | H9: 115882 | I9: 0388701837 | J9: 0 | L9: Nguyễn Ngọc Kỳ | M9: 1555512206 | N9: =IF(COUNTIF($B$2:B9,B9)=1,1,0) -> 1 | O9: PE1800 | P9: 1555512206 | Q9: PB15020070605 | R9: PB15020070605 | S9: Trần Thúy Ngân | T9: Trần Thúy Ngân | U9: Tổ 13, Hương Điền, Phường Long Hương, Thành phố Hồ Chí Minh | V9: Tổ 13, Hương Điền, Phường Long Hương, Thành phố Hồ Chí Minh, Việt Nam | W9: 1 | X9: KHBT | Y9: 2025 | Z9: 8 | AA9: 1 | AB9: 107298 | AC9: 8584 | AD9: 0 | AE9: 0 | AF9: TM | AG9: 01 | AH9: B1BCNA1ZA | AJ9: 0 | AK9: 10500 | AL9: 1 | AM9: 0 | AN9: 0 | AO9: 0 | AP9: NH | AQ9: 0 | AR9: 0 | AS9: 04/09/25 | AT9: 1157635 | AU9: K25TDA | AV9: 0 | AW9: 153 | AX9: 0388701837 | AZ9: 1-8/2025 | BA9: 115882 | BB9: CON NO | BC9: =RIGHT(AK9,5) -> 10500 | BD9: =AI9&"-"&BC9 -> -10500
A10: =SUBTOTAL(103,$L$2:L10) -> 9 | B10: PB15020059403 | C10: Nguyễn Văn Dũng | D10: Tổ 9, KP1, Phường Tam Long, Thành phố Hồ Chí Minh | E10: B1BIBA1ZA | F10: -10000 | G10: 8 | H10: 526681 | I10: 0916971369 | J10: T0320161611092294 | L10: Đỗ Thị Diễm Trang | M10: 1555539144 | N10: =IF(COUNTIF($B$2:B10,B10)=1,1,0) -> 1 | O10: PE1800 | P10: 1555539144 | Q10: PB15020059403 | R10: PB15020059403 | S10: Nguyễn Văn Dũng | T10: Nguyễn Văn Dũng | U10: Tổ 9, KP1, Phường Tam Long, Thành phố Hồ Chí Minh | V10: Tổ 9 KP1, Phường Long Tâm | W10: 0 | X10: KHBT | Y10: 2025 | Z10: 8 | AA10: 1 | AB10: 487668 | AC10: 39013 | AD10: 0 | AE10: 0 | AF10: TM | AG10: 01 | AH10: B1BIBA1ZA | AJ10: 0 | AK10: 10000 | AL10: 1 | AM10: 0 | AN10: 0 | AO10: 0 | AP10: NH | AQ10: 0 | AR10: 0 | AS10: 04/09/25 | AT10: 1161043 | AU10: K25TDA | AV10: 0 | AW10: 156 | AX10: 0916971369 | AY10: T0320161611092294 | AZ10: 1-8/2025 | BA10: 526681 | BB10: CON NO | BC10: =RIGHT(AK10,5) -> 10000 | BD10: =AI10&"-"&BC10 -> -10000
A11: =SUBTOTAL(103,$L$2:L11) -> 10 | B11: PB15020005360 | C11: BAN QUẢN LÝ DỰ ÁN ĐẦU TƯ XÂY DỰNG KHU VỰC BÀ RỊA (ĐĐ.TTTM-BR3) | D11: Trung tâm Thương Mại Bà Rịa, Phường Bà Rịa, Thành phố Hồ Chí Minh, Việt Nam | E11: B1BDTA1ZA | F11: -07430 | G11: 6 | H11: 7676227 | I11: 0985971725 | J11: 47M202525409710 | L11: Phạm Trần thanh Tâm | M11: 1596601661 | N11: =IF(COUNTIF($B$2:B11,B11)=1,1,0) -> 1 | O11: PE1800 | P11: 1596601661 | Q11: PB15020005360 | R11: PB15020012733 | S11: BAN QUẢN LÝ DỰ ÁN ĐẦU TƯ XÂY DỰNG KHU VỰC BÀ RỊA (ĐĐ.TTTM-BR3) | T11: BAN QUẢN LÝ DỰ ÁN ĐẦU TƯ XÂY DỰNG KHU VỰC BÀ RỊA (Đ.Cổng Chào Bà Rịa) | U11: Trung tâm Thương Mại Bà Rịa, Phường Bà Rịa, Thành phố Hồ Chí Minh, Việt Nam | V11: Số 138 Đường 27/4 Phường Bà Rịa, thành phố Hồ Chí Minh | W11: 1 | X11: HC03 | Y11: 2026 | Z11: 6 | AA11: 1 | AB11: 7107618 | AC11: 568609 | AD11: 0 | AE11: 0 | AF11: UC | AG11: null | AH11: B1BDTA1ZA | AJ11: 0 | AK11: 007430 | AL11: 0 | AM11: 0 | AN11: 0 | AO11: 0 | AP11: NH | AQ11: 0 | AR11: 0 | AS11: 02/07/26 | AT11: 1554881 | AU11: K26TDA | AV11: 0 | AW11: 3724 | AX11: 0985971725 | AY11: 47M202525409710 | AZ11: 1-6/2026 | BA11: 7676227 | BB11: CON NO | BC11: =RIGHT(AK11,5) -> 07430 | BD11: =AI11&"-"&BC11 -> -07430
A12: =SUBTOTAL(103,$L$2:L12) -> 11 | B12: PB15020005360 | C12: TRUNG TÂM QUẢN LÝ GIAO THÔNG VÀ HẠ TẦNG KỸ THUẬT THÀNH PHỐ HỒ CHÍ MINH | D12: Trung tâm Thương Mại Bà Rịa, Phường Bà Rịa, Thành phố Hồ Chí Minh, Việt Nam | E12: B1BDTA1ZA | F12: -07430 | G12: 7 | H12: 8284460 | I12: 0985971725 | J12: 47M202525409710 | L12: Phạm Trần thanh Tâm | M12: 1599797583 | N12: =IF(COUNTIF($B$2:B12,B12)=1,1,0) -> 0 | O12: PE1800 | P12: 1599797583 | Q12: PB15020005360 | R12: PB15020005360 | S12: TRUNG TÂM QUẢN LÝ GIAO THÔNG VÀ HẠ TẦNG KỸ THUẬT THÀNH PHỐ HỒ CHÍ MINH | T12: TRUNG TÂM QUẢN LÝ GIAO THÔNG VÀ HẠ TẦNG KỸ THUẬT THÀNH PHỐ HỒ CHÍ MINH | U12: Trung tâm Thương Mại Bà Rịa, Phường Bà Rịa, Thành phố Hồ Chí Minh, Việt Nam | V12: Số 360 đường Võ Nguyên Giáp, phường Phước Long, Thành phố Hồ Chí Minh. | W12: 1 | X12: KHNS | Y12: 2026 | Z12: 7 | AA12: 1 | AB12: 7670796 | AC12: 613664 | AD12: 0 | AE12: 0 | AF12: UC | AG12: 48 | AH12: B1BDTA1ZA | AJ12: 0 | AK12: 007430 | AL12: 0 | AM12: 0 | AN12: 0 | AO12: 0 | AP12: NH | AQ12: 0 | AR12: 0 | AS12: 02/08/26 | AT12: 1792230 | AU12: K26TDA | AV12: 0 | AW12: 5463 | AX12: 0985971725 | AY12: 47M202525409710 | AZ12: 1-7/2026 | BA12: 8284460 | BB12: CON NO | BC12: =RIGHT(AK12,5) -> 07430 | BD12: =AI12&"-"&BC12 -> -07430
A13: =SUBTOTAL(103,$L$2:L13) -> 12 | B13: PB15020081500 | C13: Nguyễn Thị Kim Phượng | D13: Tổ 8, KP4, Phường Bà Rịa, Thành phố Hồ Chí Minh | E13: B1BEPA1ZA | F13: -07140 | G13: 7 | H13: 827604 | I13: 0793630458 | J13: 0 | L13: Bùi Thanh Dũng | M13: 1550528593 | N13: =IF(COUNTIF($B$2:B13,B13)=1,1,0) -> 1 | O13: PE1800 | P13: 1550528593 | Q13: PB15020081500 | R13: PB15020081500 | S13: Nguyễn Thị Kim Phượng | T13: Nguyễn Thị Kim Phượng | U13: Tổ 8, KP4, Phường Bà Rịa, Thành phố Hồ Chí Minh | V13: Tổ 8 , KP4, Phường Phước Trung, TP Bà Rịa | W13: 0 | X13: KHBT | Y13: 2025 | Z13: 7 | AA13: 1 | AB13: 766300 | AC13: 61304 | AD13: 0 | AE13: 0 | AF13: TM | AG13: PB1502 | AH13: B1BEPA1ZA | AJ13: 0 | AK13: 07140 | AL13: 1 | AM13: 0 | AN13: 0 | AO13: 0 | AP13: NH | AQ13: 0 | AR13: 0 | AS13: 02/08/25 | AT13: 863442 | AU13: K25TDA | AV13: 0 | AW13: 28 | AX13: 0793630458 | AZ13: 1-7/2025 | BA13: 827604 | BB13: CON NO | BC13: =RIGHT(AK13,5) -> 07140 | BD13: =AI13&"-"&BC13 -> -07140
A14: =SUBTOTAL(103,$L$2:L14) -> 13 | B14: PB15020011159 | C14: Hồ Thị Bông | D14: Ấp Bắc 2 - Hoà Long, Phường Tam Long, Thành phố Hồ Chí Minh | E14: B1BMEA1ZA | F14: -06400 | G14: 8 | H14: 294948 | I14: 0933197073 | J14: T0320161611242134 | L14: Đỗ Thị Diễm Trang | M14: 1555378616 | N14: =IF(COUNTIF($B$2:B14,B14)=1,1,0) -> 1 | O14: PE1800 | P14: 1555378616 | Q14: PB15020011159 | R14: PB15020011159 | S14: Hồ Thị Bông | T14: Hồ Thị Bông | U14: Ấp Bắc 2 - Hoà Long, Phường Tam Long, Thành phố Hồ Chí Minh | V14: Ấp Bắc 2 - Hoà Long | W14: 0 | X14: KHBT | Y14: 2025 | Z14: 8 | AA14: 1 | AB14: 273100 | AC14: 21848 | AD14: 0 | AE14: 0 | AF14: TM | AG14: 01 | AH14: B1BMEA1ZA | AJ14: 0 | AK14: 06400 | AL14: 1 | AM14: 0 | AN14: 0 | AO14: 0 | AP14: NH | AQ14: 0 | AR14: 0 | AS14: 03/09/25 | AT14: 1091331 | AU14: K25TDA | AV14: 0 | AW14: 120 | AX14: 0933197073 | AY14: T0320161611242134 | AZ14: 1-8/2025 | BA14: 294948 | BB14: CON NO | BC14: =RIGHT(AK14,5) -> 06400 | BD14: =AI14&"-"&BC14 -> -06400
A15: =SUBTOTAL(103,$L$2:L15) -> 14 | B15: PB15020009335 | C15: Vũ Thị Quốc Doanh | D15: Khu 5 - Phước Hưng, Phường Long Hương, Thành phố Hồ Chí Minh | E15: B1BTEA1ZA | F15: -06020 | G15: 8 | H15: 420898 | I15: 0961616849 | J15: T0320161611722233 | L15: Nguyễn Ngọc Kỳ | M15: 1555540691 | N15: =IF(COUNTIF($B$2:B15,B15)=1,1,0) -> 1 | O15: PE1800 | P15: 1555540691 | Q15: PB15020009335 | R15: PB15020009335 | S15: Vũ Thị Quốc Doanh | T15: Vũ Thị Quốc Doanh | U15: Khu 5 - Phước Hưng, Phường Long Hương, Thành phố Hồ Chí Minh | V15: Khu 5 - Phước Hưng | W15: 0 | X15: NDAN | Y15: 2025 | Z15: 8 | AA15: 1 | AB15: 389720 | AC15: 31178 | AD15: 0 | AE15: 0 | AF15: TM | AG15: 01 | AH15: B1BTEA1ZA | AJ15: 0 | AK15: 06020 | AL15: 1 | AM15: 0 | AN15: 0 | AO15: 0 | AP15: BL | AQ15: 0 | AR15: 0 | AS15: 04/09/25 | AT15: 1163452 | AU15: K25TDA | AV15: 0 | AW15: 157 | AX15: 0961616849 | AY15: T0320161611722233 | AZ15: 1-8/2025 | BA15: 420898 | BB15: CON NO | BC15: =RIGHT(AK15,5) -> 06020 | BD15: =AI15&"-"&BC15 -> -06020
A16: =SUBTOTAL(103,$L$2:L16) -> 15 | B16: PB15020052032 | C16: Hợp Tác Xã Hòa Thành | D16: Hòa Long, Phường Tam Long, Thành phố Hồ Chí Minh, Việt Nam | E16: B1BLOA1ZA | F16: -05000 | G16: 7 | H16: 199574 | I16: 0913459057 | J16: 0 | L16: Đỗ Thị Diễm Trang | M16: 1547919274 | N16: =IF(COUNTIF($B$2:B16,B16)=1,1,0) -> 1 | O16: PE1800 | P16: 1547919274 | Q16: PB15020052032 | R16: PB15020052032 | S16: Hợp Tác Xã Hòa Thành | T16: Hợp Tác Xã Hòa Thành | U16: Hòa Long, Phường Tam Long, Thành phố Hồ Chí Minh, Việt Nam | V16: Ấp Nam, Xã Hòa Long, Thành phố Bà Rịa | W16: 1 | X16: CQTC | Y16: 2025 | Z16: 7 | AA16: 1 | AB16: 184791 | AC16: 14783 | AD16: 0 | AE16: 0 | AF16: TM | AG16: PB1502 | AH16: B1BLOA1ZA | AJ16: 0 | AK16: 05000 | AL16: 1 | AM16: 0 | AN16: 0 | AO16: 0 | AP16: NH | AQ16: 0 | AR16: 0 | AS16: 02/08/25 | AT16: 775390 | AU16: K25TDA | AV16: 0 | AW16: 18 | AX16: 0913459057 | AZ16: 1-7/2025 | BA16: 199574 | BB16: CON NO | BC16: =RIGHT(AK16,5) -> 05000 | BD16: =AI16&"-"&BC16 -> -05000
A17: =SUBTOTAL(103,$L$2:L17) -> 16 | B17: PB15020055077 | C17: Trần Thị Ngọc Hà | D17: Ấp Bắc, Phường Tam Long, Thành phố Hồ Chí Minh | E17: B1BMMA1ZA | F17: -04720 | G17: 7 | H17: 1088100 | I17: 0908047008 | J17: T032021211100008452 | L17: Đỗ Thị Diễm Trang | M17: 1547920375 | N17: =IF(COUNTIF($B$2:B17,B17)=1,1,0) -> 1 | O17: PE1800 | P17: 1547920375 | Q17: PB15020055077 | R17: PB15020055077 | S17: Trần Thị Ngọc Hà | T17: Trần Thị Ngọc Hà | U17: Ấp Bắc, Phường Tam Long, Thành phố Hồ Chí Minh | V17: Ấp Bắc xã Hoà Long-TP.BR | W17: 0 | X17: KHBT | Y17: 2025 | Z17: 7 | AA17: 1 | AB17: 1007500 | AC17: 80600 | AD17: 0 | AE17: 0 | AF17: TM | AG17: 01 | AH17: B1BMMA1ZA | AJ17: 0 | AK17: 04720 | AL17: 1 | AM17: 0 | AN17: 0 | AO17: 0 | AP17: BL | AQ17: 0 | AR17: 0 | AS17: 02/08/25 | AT17: 776918 | AU17: K25TDA | AV17: 0 | AW17: 19 | AX17: 0908047008 | AY17: T032021211100008452 | AZ17: 1-7/2025 | BA17: 1088100 | BB17: CON NO | BC17: =RIGHT(AK17,5) -> 04720 | BD17: =AI17&"-"&BC17 -> -04720
A18: =SUBTOTAL(103,$L$2:L18) -> 17 | B18: PB15020063659 | C18: BAN QUẢN LÝ DỰ ÁN ĐẦU TƯ XÂY DỰNG KHU VỰC BÀ RỊA (Hoa viên TTHC tỉnh) | D18: phường Bà Rịa, Thành Phố Hồ Chí Minh | E18: B1BDDA1ZA | F18: -03001 | G18: 6 | H18: 2694974 | I18: 0909295840 | J18: 05N202525700324 | L18: Phạm Trần thanh Tâm | M18: 1596600646 | N18: =IF(COUNTIF($B$2:B18,B18)=1,1,0) -> 1 | O18: PE1800 | P18: 1596600646 | Q18: PB15020063659 | R18: PB15020012733 | S18: BAN QUẢN LÝ DỰ ÁN ĐẦU TƯ XÂY DỰNG KHU VỰC BÀ RỊA (Hoa viên TTHC tỉnh) | T18: BAN QUẢN LÝ DỰ ÁN ĐẦU TƯ XÂY DỰNG KHU VỰC BÀ RỊA (Đ.Cổng Chào Bà Rịa) | U18: phường Bà Rịa, Thành Phố Hồ Chí Minh | V18: Số 138 Đường 27/4 Phường Bà Rịa, thành phố Hồ Chí Minh | W18: 1 | X18: HC03 | Y18: 2026 | Z18: 6 | AA18: 1 | AB18: 2495346 | AC18: 199628 | AD18: 0 | AE18: 0 | AF18: UC | AG18: null | AH18: B1BDDA1ZA | AJ18: 0 | AK18: 003001 | AL18: 0 | AM18: 0 | AN18: 0 | AO18: 0 | AP18: NH | AQ18: 0 | AR18: 0 | AS18: 02/07/26 | AT18: 1554695 | AU18: K26TDA | AV18: 0 | AW18: 3720 | AX18: 0909295840 | AY18: 05N202525700324 | AZ18: 1-6/2026 | BA18: 2694974 | BB18: CON NO | BC18: =RIGHT(AK18,5) -> 03001 | BD18: =AI18&"-"&BC18 -> -03001
A19: =SUBTOTAL(103,$L$2:L19) -> 18 | B19: PB15020063659 | C19: BAN QUẢN LÝ DỰ ÁN ĐẦU TƯ XÂY DỰNG KHU VỰC BÀ RỊA (Hoa viên TTHC tỉnh) | D19: phường Bà Rịa, Thành Phố Hồ Chí Minh | E19: B1BDDA1ZA | F19: -03001 | G19: 7 | H19: 3411390 | I19: 0909295840 | J19: 05N202525700324 | L19: Phạm Trần thanh Tâm | M19: 1599797476 | N19: =IF(COUNTIF($B$2:B19,B19)=1,1,0) -> 0 | O19: PE1800 | P19: 1599797476 | Q19: PB15020063659 | R19: PB15020012733 | S19: BAN QUẢN LÝ DỰ ÁN ĐẦU TƯ XÂY DỰNG KHU VỰC BÀ RỊA (Hoa viên TTHC tỉnh) | T19: TRUNG TÂM QUẢN LÝ GIAO THÔNG VÀ HẠ TẦNG KỸ THUẬT THÀNH PHỐ HỒ CHÍ MINH | U19: phường Bà Rịa, Thành Phố Hồ Chí Minh | V19: Số 360 đường Võ Nguyên Giáp, phường Phước Long, Thành phố Hồ Chí Minh, Việt Nam. | W19: 1 | X19: HC03 | Y19: 2026 | Z19: 7 | AA19: 1 | AB19: 3158694 | AC19: 252696 | AD19: 0 | AE19: 0 | AF19: UC | AG19: null | AH19: B1BDDA1ZA | AJ19: 0 | AK19: 003001 | AL19: 0 | AM19: 0 | AN19: 0 | AO19: 0 | AP19: NH | AQ19: 0 | AR19: 0 | AS19: 02/08/26 | AT19: 1792041 | AU19: K26TDA | AV19: 0 | AW19: 5449 | AX19: 0909295840 | AY19: 05N202525700324 | AZ19: 1-7/2026 | BA19: 3411390 | BB19: CON NO | BC19: =RIGHT(AK19,5) -> 03001 | BD19: =AI19&"-"&BC19 -> -03001
A20: =SUBTOTAL(103,$L$2:L20) -> 19 | B20: PB15020064374 | C20: Sở Lao Động-Thương Binh-Xã Hội tỉnh Bà Rịa - Vũng Tàu | D20: 11 Trường Chinh, Phường Bà Rịa, Thành phố Hồ Chí Minh, Việt Nam | E20: B1BCQB2ZA | F20: -02970 | G20: 8 | H20: 3363308 | I20: 0978577377 | J20: 28M201717086753 | L20: Phạm Trần thanh Tâm | M20: 1552233305 | N20: =IF(COUNTIF($B$2:B20,B20)=1,1,0) -> 1 | O20: PE1800 | P20: 1552233305 | Q20: PB15020064374 | R20: PB15020064374 | S20: Sở Lao Động-Thương Binh-Xã Hội tỉnh Bà Rịa - Vũng Tàu | T20: Sở Lao Động-Thương Binh-Xã Hội tỉnh Bà Rịa - Vũng Tàu | U20: 11 Trường Chinh, Phường Bà Rịa, Thành phố Hồ Chí Minh, Việt Nam | V20: 11 Trường Chinh, Phường Phước Trung, Thành phố Bà Rịa, tỉnh BR-VT | W20: 1 | X20: KHNS | Y20: 2025 | Z20: 8 | AA20: 1 | AB20: 3114174 | AC20: 249134 | AD20: 0 | AE20: 0 | AF20: UC | AG20: 01 | AH20: B1BCQB2ZA | AJ20: 0 | AK20: 02970 | AL20: 1 | AM20: 0 | AN20: 0 | AO20: 0 | AP20: NH | AQ20: 0 | AR20: 0 | AS20: 02/09/25 | AT20: 962743 | AU20: K25TDA | AV20: 0 | AW20: 99 | AX20: 0978577377 | AY20: 28M201717086753 | AZ20: 1-8/2025 | BA20: 3363308 | BB20: CON NO | BC20: =RIGHT(AK20,5) -> 02970 | BD20: =AI20&"-"&BC20 -> -02970
A21: =SUBTOTAL(103,$L$2:L21) -> 20 | B21: PB15020078123 | C21: BAN QUẢN LÝ DỰ ÁN ĐẦU TƯ XÂY DỰNG KHU VỰC BÀ RỊA (Đường Trường Chin) | D21: Đường Trường Chinh, Phường Bà Rịa, Thành phố Hồ Chí Minh, Việt Nam | E21: B1BCQB2ZA | F21: -02927 | G21: 6 | H21: 5933269 | I21: 0985971725 | J21: 02N201818512936 | L21: Phạm Trần thanh Tâm | M21: 1596856675 | N21: =IF(COUNTIF($B$2:B21,B21)=1,1,0) -> 1 | O21: PE1800 | P21: 1596856675 | Q21: PB15020078123 | R21: PB15020012733 | S21: BAN QUẢN LÝ DỰ ÁN ĐẦU TƯ XÂY DỰNG KHU VỰC BÀ RỊA (Đường Trường Chin) | T21: BAN QUẢN LÝ DỰ ÁN ĐẦU TƯ XÂY DỰNG KHU VỰC BÀ RỊA (Đ.Cổng Chào Bà Rịa) | U21: Đường Trường Chinh, Phường Bà Rịa, Thành phố Hồ Chí Minh, Việt Nam | V21: Số 138 Đường 27/4 Phường Bà Rịa, thành phố Hồ Chí Minh | W21: 1 | X21: HC03 | Y21: 2026 | Z21: 6 | AA21: 1 | AB21: 5493768 | AC21: 439501 | AD21: 0 | AE21: 0 | AF21: TM | AG21: null | AH21: B1BCQB2ZA | AJ21: 0 | AK21: 002927 | AL21: 0 | AM21: 0 | AN21: 0 | AO21: 0 | AP21: NH | AQ21: 0 | AR21: 0 | AS21: 02/07/26 | AT21: 1553556 | AU21: K26TDA | AV21: 0 | AW21: 3833 | AX21: 0985971725 | AY21: 02N201818512936 | AZ21: 1-6/2026 | BA21: 5933269 | BB21: CON NO | BC21: =RIGHT(AK21,5) -> 02927 | BD21: =AI21&"-"&BC21 -> -02927
A22: =SUBTOTAL(103,$L$2:L22) -> 21 | B22: PB15020078123 | C22: TRUNG TÂM QUẢN LÝ GIAO THÔNG VÀ HẠ TẦNG KỸ THUẬT THÀNH PHỐ HỒ CHÍ MINH | D22: Đường Trường Chinh, Phường Bà Rịa, Thành phố Hồ Chí Minh, Việt Nam | E22: B1BCQB2ZA | F22: -02927 | G22: 7 | H22: 5724114 | I22: 0985971725 | J22: 02N201818512936 | L22: Phạm Trần thanh Tâm | M22: 1601133522 | N22: =IF(COUNTIF($B$2:B22,B22)=1,1,0) -> 0 | O22: PE1800 | P22: 1601133522 | Q22: PB15020078123 | R22: PB15020078123 | S22: TRUNG TÂM QUẢN LÝ GIAO THÔNG VÀ HẠ TẦNG KỸ THUẬT THÀNH PHỐ HỒ CHÍ MINH | T22: TRUNG TÂM QUẢN LÝ GIAO THÔNG VÀ HẠ TẦNG KỸ THUẬT THÀNH PHỐ HỒ CHÍ MINH | U22: Đường Trường Chinh, Phường Bà Rịa, Thành phố Hồ Chí Minh, Việt Nam | V22: Số 360 đường Võ Nguyên Giáp, Phường Phước Long, Thành phố Hồ Chí Minh, Việt Nam | W22: 1 | X22: HC03 | Y22: 2026 | Z22: 7 | AA22: 1 | AB22: 5300106 | AC22: 424008 | AD22: 0 | AE22: 0 | AF22: TM | AG22: null | AH22: B1BCQB2ZA | AJ22: 0 | AK22: 002927 | AL22: 0 | AM22: 0 | AN22: 0 | AO22: 0 | AP22: NH | AQ22: 0 | AR22: 0 | AS22: 02/08/26 | AT22: 1790893 | AU22: K26TDA | AV22: 0 | AW22: 20826 | AX22: 0985971725 | AY22: 02N201818512936 | AZ22: 1-7/2026 | BA22: 5724114 | BB22: CON NO | BC22: =RIGHT(AK22,5) -> 02927 | BD22: =AI22&"-"&BC22 -> -02927
A23: =SUBTOTAL(103,$L$2:L23) -> 22 | B23: PB15020064360 | C23: BAN TỔ CHỨC THÀNH ỦY THÀNH PHỐ HỒ CHÍ MINH | D23: 198 Bạch Đằng, phường Bà Rịa, thành Phố Hồ Chí Minh | E23: B1BCQB2ZA | F23: -02860 | G23: 7 | H23: 1019330 | I23: 0945234879 | J23: 28M201616089745 | L23: Phạm Trần Thanh Tâm | M23: 1601133553 | N23: =IF(COUNTIF($B$2:B23,B23)=1,1,0) -> 1 | O23: PE1800 | P23: 1601133553 | Q23: PB15020064360 | R23: PB15020064360 | S23: BAN TỔ CHỨC THÀNH ỦY THÀNH PHỐ HỒ CHÍ MINH | T23: BAN TỔ CHỨC THÀNH ỦY THÀNH PHỐ HỒ CHÍ MINH | U23: 198 Bạch Đằng, phường Bà Rịa, thành Phố Hồ Chí Minh | V23: 127 Trương Định, Phường Xuân Hoà, Thành phố Hồ Chí Minh, Việt Nam | W23: 1 | X23: KHNS | Y23: 2026 | Z23: 7 | AA23: 1 | AB23: 943824 | AC23: 75506 | AD23: 0 | AE23: 0 | AF23: UC | AG23: null | AH23: B1BCQB2ZA | AJ23: 0 | AK23: 002860 | AL23: 0 | AM23: 0 | AN23: 0 | AO23: 0 | AP23: UC | AQ23: 0 | AR23: 0 | AS23: 02/08/26 | AT23: 1790891 | AU23: K26TDA | AV23: 0 | AW23: 20838 | AX23: 0945234879 | AY23: 28M201616089745 | AZ23: 1-7/2026 | BA23: 1019330 | BB23: CON NO | BC23: =RIGHT(AK23,5) -> 02860 | BD23: =AI23&"-"&BC23 -> -02860
A24: =SUBTOTAL(103,$L$2:L24) -> 23 | B24: PB15020064385 | C24: SỞ XÂY DỰNG THÀNH PHỐ HỒ CHÍ MINH | D24: 198 Bạch Đằng, Phường Bà Rịa, Thành phố Hồ Chí Minh, Việt Nam | E24: B1BCQB2ZA | F24: -02830 | G24: 7 | H24: 6649685 | I24: 0909722780 | J24: 28M201818083618 | L24: Phạm Trần thanh Tâm | M24: 1601133537 | N24: =IF(COUNTIF($B$2:B24,B24)=1,1,0) -> 1 | O24: PE1800 | P24: 1601133537 | Q24: PB15020064385 | R24: PB15020013346 | S24: SỞ XÂY DỰNG THÀNH PHỐ HỒ CHÍ MINH | T24: SỞ XÂY DỰNG THÀNH PHỐ HỒ CHÍ MINH | U24: 198 Bạch Đằng, Phường Bà Rịa, Thành phố Hồ Chí Minh, Việt Nam | V24: 63 Lý Tự Trọng, Phường Sài Gòn, Thành phố Hồ Chí Minh, Việt Nam | W24: 1 | X24: KHNS | Y24: 2026 | Z24: 7 | AA24: 1 | AB24: 6157116 | AC24: 492569 | AD24: 0 | AE24: 0 | AF24: UC | AG24: null | AH24: B1BCQB2ZA | AJ24: 0 | AK24: 002830 | AL24: 0 | AM24: 0 | AN24: 0 | AO24: 0 | AP24: UC | AQ24: 0 | AR24: 0 | AS24: 02/08/26 | AT24: 1790890 | AU24: K26TDA | AV24: 0 | AW24: 20831 | AX24: 0909722780 | AY24: 28M201818083618 | AZ24: 1-7/2026 | BA24: 6649685 | BB24: CON NO | BC24: =RIGHT(AK24,5) -> 02830 | BD24: =AI24&"-"&BC24 -> -02830
A25: =SUBTOTAL(103,$L$2:L25) -> 24 | B25: PB15020064384 | C25: SỞ XÂY DỰNG THÀNH PHỐ HỒ CHÍ MINH | D25: Khu B3 Bạch Đằng, Phường Bà Rịa, Thành phố Hồ Chí Minh, Việt Nam | E25: B1BCQB2ZA | F25: -02825 | G25: 7 | H25: 4204736 | I25: 0909722780 | J25: 28M201717026144 | L25: Phạm Trần thanh Tâm | M25: 1601133550 | N25: =IF(COUNTIF($B$2:B25,B25)=1,1,0) -> 1 | O25: PE1800 | P25: 1601133550 | Q25: PB15020064384 | R25: PB15020013346 | S25: SỞ XÂY DỰNG THÀNH PHỐ HỒ CHÍ MINH | T25: SỞ XÂY DỰNG THÀNH PHỐ HỒ CHÍ MINH | U25: Khu B3 Bạch Đằng, Phường Bà Rịa, Thành phố Hồ Chí Minh, Việt Nam | V25: 63 Lý Tự Trọng, Phường Sài Gòn, Thành phố Hồ Chí Minh, Việt Nam | W25: 1 | X25: KHNS | Y25: 2026 | Z25: 7 | AA25: 1 | AB25: 3893274 | AC25: 311462 | AD25: 0 | AE25: 0 | AF25: UC | AG25: null | AH25: B1BCQB2ZA | AJ25: 0 | AK25: 002825 | AL25: 0 | AM25: 0 | AN25: 0 | AO25: 0 | AP25: UC | AQ25: 0 | AR25: 0 | AS25: 02/08/26 | AT25: 1790889 | AU25: K26TDA | AV25: 0 | AW25: 20837 | AX25: 0909722780 | AY25: 28M201717026144 | AZ25: 1-7/2026 | BA25: 4204736 | BB25: CON NO | BC25: =RIGHT(AK25,5) -> 02825 | BD25: =AI25&"-"&BC25 -> -02825
A26: =SUBTOTAL(103,$L$2:L26) -> 25 | B26: PB15020064382 | C26: SỞ NÔNG NGHIỆP VÀ MÔI TRƯỜNG THÀNH PHỐ HỒ CHÍ MINH | D26: 01 Phạm Văn Đồng, Phường Bà Rịa, Thành Phố Hồ Chí Minh | E26: B1BCQB2ZA | F26: -02815 | G26: 7 | H26: 7084824 | I26: 0762488449 | J26: 0 | L26: Phạm Trần thanh Tâm | M26: 1601133535 | N26: =IF(COUNTIF($B$2:B26,B26)=1,1,0) -> 1 | O26: PE1800 | P26: 1601133535 | Q26: PB15020064382 | R26: PB15020010514 | S26: SỞ NÔNG NGHIỆP VÀ MÔI TRƯỜNG THÀNH PHỐ HỒ CHÍ MINH | T26: SỞ NÔNG NGHIỆP VÀ MÔI TRƯỜNG THÀNH PHỐ HỒ CHÍ MINH | U26: 01 Phạm Văn Đồng, Phường Bà Rịa, Thành Phố Hồ Chí Minh | V26: Số 63, Đường Lý Tự Trọng, Phường Sài Gòn, Thành phố Hồ Chí Minh | W26: 1 | X26: KHNS | Y26: 2026 | Z26: 7 | AA26: 1 | AB26: 6560022 | AC26: 524802 | AD26: 0 | AE26: 0 | AF26: UC | AG26: null | AH26: B1BCQB2ZA | AJ26: 0 | AK26: 002815 | AL26: 0 | AM26: 0 | AN26: 0 | AO26: 0 | AP26: UC | AQ26: 0 | AR26: 0 | AS26: 02/08/26 | AT26: 1790887 | AU26: K26TDA | AV26: 0 | AW26: 20830 | AX26: 0762488449 | AZ26: 1-7/2026 | BA26: 7084824 | BB26: CON NO | BC26: =RIGHT(AK26,5) -> 02815 | BD26: =AI26&"-"&BC26 -> -02815
A27: =SUBTOTAL(103,$L$2:L27) -> 26 | B27: PB15020064363 | C27: Ban Dân Vận Tỉnh ủy tỉnh Bà Rịa - Vũng Tàu | D27: 198 Bạch Đằng, Phường Bà Rịa, Thành phố Hồ Chí Minh, Việt Nam | E27: B1BCQB2ZA | F27: -02760 | G27: 8 | H27: 2449758 | I27: 0919892428 | J27: 28M201818083602 | L27: Phạm Trần thanh Tâm | M27: 1552233279 | N27: =IF(COUNTIF($B$2:B27,B27)=1,1,0) -> 1 | O27: PE1800 | P27: 1552233279 | Q27: PB15020064363 | R27: PB15020064363 | S27: Ban Dân Vận Tỉnh ủy tỉnh Bà Rịa - Vũng Tàu | T27: Ban Dân Vận Tỉnh ủy tỉnh Bà Rịa - Vũng Tàu | U27: 198 Bạch Đằng, Phường Bà Rịa, Thành phố Hồ Chí Minh, Việt Nam | V27: 198 Bạch Đằng, Phường Phước Trung, Thành phố Bà Rịa, tỉnh Bà Rịa - Vũng Tàu | W27: 1 | X27: KHNS | Y27: 2025 | Z27: 8 | AA27: 1 | AB27: 2268294 | AC27: 181464 | AD27: 0 | AE27: 0 | AF27: UC | AG27: 01 | AH27: B1BCQB2ZA | AJ27: 0 | AK27: 02760 | AL27: 1 | AM27: 0 | AN27: 0 | AO27: 0 | AP27: NH | AQ27: 0 | AR27: 0 | AS27: 02/09/25 | AT27: 962719 | AU27: K25TDA | AV27: 0 | AW27: 98 | AX27: 0919892428 | AY27: 28M201818083602 | AZ27: 1-8/2025 | BA27: 2449758 | BB27: CON NO | BC27: =RIGHT(AK27,5) -> 02760 | BD27: =AI27&"-"&BC27 -> -02760
A28: =SUBTOTAL(103,$L$2:L28) -> 27 | B28: PB15020024719 | C28: Bùi Thị Hiền | D28: Khu 5 Phước Hưng, Phường Long Hương, Thành phố Hồ Chí Minh | E28: B1BTAA1ZA | F28: -02220 | G28: 8 | H28: 433750 | I28: 0 | J28: 0 | L28: Nguyễn Ngọc Kỳ | M28: 1555502438 | N28: =IF(COUNTIF($B$2:B28,B28)=1,1,0) -> 1 | O28: PE1800 | P28: 1555502438 | Q28: PB15020024719 | R28: PB15020024719 | S28: Bùi Thị Hiền | T28: Bùi Thị Hiền | U28: Khu 5 Phước Hưng, Phường Long Hương, Thành phố Hồ Chí Minh | V28: Xã Tân Hưnng-TPBR | W28: 0 | X28: KHBT | Y28: 2025 | Z28: 8 | AA28: 1 | AB28: 401620 | AC28: 32130 | AD28: 0 | AE28: 0 | AF28: TM | AG28: 09 | AH28: B1BTAA1ZA | AJ28: 0 | AK28: 02220 | AL28: 1 | AM28: 0 | AN28: 0 | AO28: 0 | AP28: NH | AQ28: 0 | AR28: 0 | AS28: 03/09/25 | AT28: 1130082 | AU28: K25TDA | AV28: 0 | AW28: 150 | AZ28: 1-8/2025 | BA28: 433750 | BB28: CON NO | BC28: =RIGHT(AK28,5) -> 02220 | BD28: =AI28&"-"&BC28 -> -02220
A29: =SUBTOTAL(103,$L$2:L29) -> 28 | B29: PB15020066060 | C29: Đỗ Thanh Đạm | D29: Ấp Bắc 2 - Hoà Long, Phường Tam Long, Thành phố Hồ Chí Minh, Việt Nam | E29: B1BMXA1ZA | F29: -02215 | G29: 7 | H29: 201720 | I29: 0999125642 | J29: M2B20191920028281 | L29: Đỗ Thị Diễm Trang | M29: 1547920645 | N29: =IF(COUNTIF($B$2:B29,B29)=1,1,0) -> 1 | O29: PE1800 | P29: 1547920645 | Q29: PB15020066060 | R29: PB15020066060 | S29: Đỗ Thanh Đạm | T29: Đỗ Thanh Đạm | U29: Ấp Bắc 2 - Hoà Long, Phường Tam Long, Thành phố Hồ Chí Minh, Việt Nam | V29: Ấp Bắc 2, Xã Hoà Long, Thành phố Bà Rịa. | W29: 1 | X29: KHBT | Y29: 2025 | Z29: 7 | AA29: 1 | AB29: 186778 | AC29: 14942 | AD29: 0 | AE29: 0 | AF29: DT | AG29: 1 | AH29: B1BMXA1ZA | AJ29: 0 | AK29: 02215 | AL29: 1 | AM29: 0 | AN29: 0 | AO29: 0 | AP29: NH | AQ29: 0 | AR29: 0 | AS29: 02/08/25 | AT29: 777527 | AU29: K25TDA | AV29: 0 | AW29: 20 | AX29: 0999125642 | AY29: M2B20191920028281 | AZ29: 1-7/2025 | BA29: 201720 | BB29: CON NO | BC29: =RIGHT(AK29,5) -> 02215 | BD29: =AI29&"-"&BC29 -> -02215
A30: =SUBTOTAL(103,$L$2:L30) -> 29 | B30: PE18000000207 | C30: CHI NHÁNH - CÔNG TY TNHH NEW GREEN WAY VIỆT NAM | D30: số 261 Quốc lộ 51, phường Long Hương, thành phố Hồ Chí Minh | E30: B1BAMA1ZA | F30: -02210 | G30: 7 | H30: 83886 | I30: 0982352286 | J30: 47M202525414683 | L30: Nguyễn Ngọc Kỳ | M30: 1601129868 | N30: =IF(COUNTIF($B$2:B30,B30)=1,1,0) -> 1 | O30: PE1800 | P30: 1601129868 | Q30: PE18000000207 | R30: PE18000000207 | S30: CHI NHÁNH - CÔNG TY TNHH NEW GREEN WAY VIỆT NAM | T30: CHI NHÁNH - CÔNG TY TNHH NEW GREEN WAY VIỆT NAM | U30: số 261 Quốc lộ 51, phường Long Hương, thành phố Hồ Chí Minh | V30: số 261 Quốc lộ 51, phường Long Hương, thành phố Hồ Chí Minh | W30: 1 | X30: TMDV | Y30: 2026 | Z30: 7 | AA30: 1 | AB30: 77672 | AC30: 6214 | AD30: 0 | AE30: 0 | AF30: DT | AG30: 01 | AH30: B1BAMA1ZA | AJ30: 0 | AK30: 002210 | AL30: 0 | AM30: 0 | AN30: 0 | AO30: 0 | AP30: NH | AQ30: 0 | AR30: 0 | AS30: 02/08/26 | AT30: 1786202 | AU30: K26TDA | AV30: 0 | AW30: 20090 | AX30: 0982352286 | AY30: 47M202525414683 | AZ30: 1-7/2026 | BA30: 83886 | BB30: CON NO | BC30: =RIGHT(AK30,5) -> 02210 | BD30: =AI30&"-"&BC30 -> -02210
A31: =SUBTOTAL(103,$L$2:L31) -> 30 | B31: PB15020060183 | C31: CÔNG AN THÀNH PHỐ HỒ CHÍ MINH | D31: 15 Trường Chinh, Phường Bà Rịa, Thành phố Hồ Chí Minh, Việt Nam | E31: B1BPPA3ZA | F31: -02000 | G31: 7 | H31: 62951358 | I31: 0937433522 | J31: 28M201414223529 | L31: Phạm Trần thanh Tâm | M31: 1599799257 | N31: =IF(COUNTIF($B$2:B31,B31)=1,1,0) -> 1 | O31: PE1800 | P31: 1599799257 | Q31: PB15020060183 | R31: PB15020060183 | S31: CÔNG AN THÀNH PHỐ HỒ CHÍ MINH | T31: CÔNG AN THÀNH PHỐ HỒ CHÍ MINH | U31: 15 Trường Chinh, Phường Bà Rịa, Thành phố Hồ Chí Minh, Việt Nam | V31: Số 268 Trần Hưng Đạo, Phường Cầu Ông Lãnh, TP Hồ Chí Minh, Việt Nam | W31: 1 | X31: KHNS | Y31: 2026 | Z31: 7 | AA31: 1 | AB31: 58288294 | AC31: 4663064 | AD31: 0 | AE31: 0 | AF31: UC | AG31: PB1502 | AH31: B1BPPA3ZA | AJ31: 0 | AK31: 002000 | AL31: 0 | AM31: 0 | AN31: 0 | AO31: 0 | AP31: UC | AQ31: 0 | AR31: 0 | AS31: 02/08/26 | AT31: 1821881 | AU31: K26TDA | AV31: 0 | AW31: 5666 | AX31: 0937433522 | AY31: 28M201414223529 | AZ31: 1-7/2026 | BA31: 62951358 | BB31: CON NO | BC31: =RIGHT(AK31,5) -> 02000 | BD31: =AI31&"-"&BC31 -> -02000
A32: =SUBTOTAL(103,$L$2:L32) -> 31 | B32: PB15020062901 | C32: BAN QUẢN LÝ DỰ ÁN ĐẦU TƯ XÂY DỰNG KHU VỰC BÀ RỊA (ĐĐ3.Tr Chinh) | D32: Trụ 75BR-68/23/16/9 Trường Chinh, Phường Bà Rịa, TP. Hồ Chí Minh, Việt Nam | E32: B1BCQB2ZA | F32: -01800 | G32: 6 | H32: 798155 | I32: 0985971725 | J32: T44202525000941 | L32: Phạm Trần thanh Tâm | M32: 1596856759 | N32: =IF(COUNTIF($B$2:B32,B32)=1,1,0) -> 1 | O32: PE1800 | P32: 1596856759 | Q32: PB15020062901 | R32: PB15020012733 | S32: BAN QUẢN LÝ DỰ ÁN ĐẦU TƯ XÂY DỰNG KHU VỰC BÀ RỊA (ĐĐ3.Tr Chinh) | T32: BAN QUẢN LÝ DỰ ÁN ĐẦU TƯ XÂY DỰNG KHU VỰC BÀ RỊA (Đ.Cổng Chào Bà Rịa) | U32: Trụ 75BR-68/23/16/9 Trường Chinh, Phường Bà Rịa, TP. Hồ Chí Minh, Việt Nam | V32: Số 138 Đường 27/4 Phường Bà Rịa, thành phố Hồ Chí Minh | W32: 1 | X32: HC03 | Y32: 2026 | Z32: 6 | AA32: 1 | AB32: 739032 | AC32: 59123 | AD32: 0 | AE32: 0 | AF32: UC | AG32: null | AH32: B1BCQB2ZA | AJ32: 0 | AK32: 001800 | AL32: 0 | AM32: 0 | AN32: 0 | AO32: 0 | AP32: NH | AQ32: 0 | AR32: 0 | AS32: 02/07/26 | AT32: 1553549 | AU32: K26TDA | AV32: 0 | AW32: 3840 | AX32: 0985971725 | AY32: T44202525000941 | AZ32: 1-6/2026 | BA32: 798155 | BB32: CON NO | BC32: =RIGHT(AK32,5) -> 01800 | BD32: =AI32&"-"&BC32 -> -01800
A33: =SUBTOTAL(103,$L$2:L33) -> 32 | B33: PB15020062901 | C33: TRUNG TÂM QUẢN LÝ GIAO THÔNG VÀ HẠ TẦNG KỸ THUẬT THÀNH PHỐ HỒ CHÍ MINH | D33: Trụ 75BR-68/23/16/9 Trường Chinh, Phường Bà Rịa, TP. Hồ Chí Minh, Việt Nam | E33: B1BCQB2ZA | F33: -01800 | G33: 7 | H33: 908742 | I33: 0985971725 | J33: T44202525000941 | L33: Phạm Trần thanh Tâm | M33: 1601133585 | N33: =IF(COUNTIF($B$2:B33,B33)=1,1,0) -> 0 | O33: PE1800 | P33: 1601133585 | Q33: PB15020062901 | R33: PB15020062901 | S33: TRUNG TÂM QUẢN LÝ GIAO THÔNG VÀ HẠ TẦNG KỸ THUẬT THÀNH PHỐ HỒ CHÍ MINH | T33: TRUNG TÂM QUẢN LÝ GIAO THÔNG VÀ HẠ TẦNG KỸ THUẬT THÀNH PHỐ HỒ CHÍ MINH | U33: Trụ 75BR-68/23/16/9 Trường Chinh, Phường Bà Rịa, TP. Hồ Chí Minh, Việt Nam | V33: Số 360 đường Võ Nguyên Giáp, Phường Phước Long, Thành phố Hồ Chí Minh, Việt Nam | W33: 1 | X33: HC03 | Y33: 2026 | Z33: 7 | AA33: 1 | AB33: 841428 | AC33: 67314 | AD33: 0 | AE33: 0 | AF33: UC | AG33: null | AH33: B1BCQB2ZA | AJ33: 0 | AK33: 001800 | AL33: 0 | AM33: 0 | AN33: 0 | AO33: 0 | AP33: NH | AQ33: 0 | AR33: 0 | AS33: 02/08/26 | AT33: 1790886 | AU33: K26TDA | AV33: 0 | AW33: 20846 | AX33: 0985971725 | AY33: T44202525000941 | AZ33: 1-7/2026 | BA33: 908742 | BB33: CON NO | BC33: =RIGHT(AK33,5) -> 01800 | BD33: =AI33&"-"&BC33 -> -01800
A34: =SUBTOTAL(103,$L$2:L34) -> 33 | B34: PB15020062992 | C34: BAN QUẢN LÝ DỰ ÁN ĐẦU TƯ XÂY DỰNG KHU VỰC BÀ RỊA (ĐĐ BCH QS tỉnh) | D34: BCH Quân sự tỉnh Hùng Vương, Phường Tam Long, Thành phố Hồ Chí Minh, Việt Nam | E34: B1BDTA1ZA | F34: -00380 | G34: 6 | H34: 2567557 | I34: 0846313484 | J34: M2B20202020120108 | L34: Phạm Trần thanh Tâm | M34: 1596601649 | N34: =IF(COUNTIF($B$2:B34,B34)=1,1,0) -> 1 | O34: PE1800 | P34: 1596601649 | Q34: PB15020062992 | R34: PB15020012733 | S34: BAN QUẢN LÝ DỰ ÁN ĐẦU TƯ XÂY DỰNG KHU VỰC BÀ RỊA (ĐĐ BCH QS tỉnh) | T34: BAN QUẢN LÝ DỰ ÁN ĐẦU TƯ XÂY DỰNG KHU VỰC BÀ RỊA (Đ.Cổng Chào Bà Rịa) | U34: BCH Quân sự tỉnh Hùng Vương, Phường Tam Long, Thành phố Hồ Chí Minh, Việt Nam | V34: Số 138 Đường 27/4 Phường Bà Rịa, thành phố Hồ Chí Minh | W34: 1 | X34: HC03 | Y34: 2026 | Z34: 6 | AA34: 1 | AB34: 2377368 | AC34: 190189 | AD34: 0 | AE34: 0 | AF34: TM | AG34: null | AH34: B1BDTA1ZA | AJ34: 0 | AK34: 000380 | AL34: 0 | AM34: 0 | AN34: 0 | AO34: 0 | AP34: NH | AQ34: 0 | AR34: 0 | AS34: 02/07/26 | AT34: 1554879 | AU34: K26TDA | AV34: 0 | AW34: 3723 | AX34: 0846313484 | AY34: M2B20202020120108 | AZ34: 1-6/2026 | BA34: 2567557 | BB34: CON NO | BC34: =RIGHT(AK34,5) -> 00380 | BD34: =AI34&"-"&BC34 -> -00380
A35: =SUBTOTAL(103,$L$2:L35) -> 34 | B35: PB15020062992 | C35: BAN QUẢN LÝ DỰ ÁN ĐẦU TƯ XÂY DỰNG KHU VỰC BÀ RỊA (ĐĐ BCH QS tỉnh) | D35: BCH Quân sự tỉnh Hùng Vương, Phường Tam Long, Thành phố Hồ Chí Minh, Việt Nam | E35: B1BDTA1ZA | F35: -00380 | G35: 7 | H35: 2690166 | I35: 0846313484 | J35: M2B20202020120108 | L35: Phạm Trần thanh Tâm | M35: 1599797573 | N35: =IF(COUNTIF($B$2:B35,B35)=1,1,0) -> 0 | O35: PE1800 | P35: 1599797573 | Q35: PB15020062992 | R35: PB15020012733 | S35: BAN QUẢN LÝ DỰ ÁN ĐẦU TƯ XÂY DỰNG KHU VỰC BÀ RỊA (ĐĐ BCH QS tỉnh) | T35: TRUNG TÂM QUẢN LÝ GIAO THÔNG VÀ HẠ TẦNG KỸ THUẬT THÀNH PHỐ HỒ CHÍ MINH | U35: BCH Quân sự tỉnh Hùng Vương, Phường Tam Long, Thành phố Hồ Chí Minh, Việt Nam | V35: Số 360 đường Võ Nguyên Giáp, phường Phước Long, Thành phố Hồ Chí Minh, Việt Nam. | W35: 1 | X35: HC03 | Y35: 2026 | Z35: 7 | AA35: 1 | AB35: 2490894 | AC35: 199272 | AD35: 0 | AE35: 0 | AF35: TM | AG35: null | AH35: B1BDTA1ZA | AJ35: 0 | AK35: 000380 | AL35: 0 | AM35: 0 | AN35: 0 | AO35: 0 | AP35: NH | AQ35: 0 | AR35: 0 | AS35: 02/08/26 | AT35: 1792228 | AU35: K26TDA | AV35: 0 | AW35: 5460 | AX35: 0846313484 | AY35: M2B20202020120108 | AZ35: 1-7/2026 | BA35: 2690166 | BB35: CON NO | BC35: =RIGHT(AK35,5) -> 00380 | BD35: =AI35&"-"&BC35 -> -00380
A36: =SUBTOTAL(103,$L$2:L36) -> 35 | B36: PB15040053024 | C36: Nguyễn Thanh Lộc | D36: KP Phước Hiệp, Phường Tân Hải, Thành phố Hồ Chí Minh | E36: B1D0239ZA | F36: 01D-01800 | G36: 7 | H36: 1795716 | I36: 0937320761 | J36: T032022221100158113 | L36: Nguyễn Bá Lạp | M36: 1601184696 | N36: =IF(COUNTIF($B$2:B36,B36)=1,1,0) -> 1 | O36: PE1800 | P36: 1601184696 | Q36: PB15040053024 | R36: PB15040053024 | S36: Nguyễn Thanh Lộc | T36: Nguyễn Thanh Lộc | U36: KP Phước Hiệp, Phường Tân Hải, Thành phố Hồ Chí Minh | V36: KP Phước Hiệp, Phường Tân Hải, Thành phố Hồ Chí Minh | W36: 0 | X36: KHBT | Y36: 2026 | Z36: 7 | AA36: 1 | AB36: 1662700 | AC36: 133016 | AD36: 0 | AE36: 0 | AF36: DT | AG36: 03 | AH36: B1D0239ZA | AI36: 01D | AJ36: 0 | AK36: 001800 | AL36: 0 | AM36: 0 | AN36: 0 | AO36: 0 | AP36: NH | AQ36: 0 | AR36: 0 | AS36: 02/08/26 | AT36: 1847260 | AU36: K26TDA | AV36: 0 | AW36: 29967 | AX36: 0937320761 | AY36: T032022221100158113 | AZ36: 1-7/2026 | BA36: 1795716 | BB36: CON NO | BC36: =RIGHT(AK36,5) -> 01800 | BD36: =AI36&"-"&BC36 -> 01D-01800
A37: =SUBTOTAL(103,$L$2:L37) -> 36 | B37: PB15040053029 | C37: Nguyễn Thị MInh | D37: Ấp Phước Hiệp, Phường Tân Hải, Thành phố Hồ Chí Minh | E37: B1D0239ZA | F37: 01D-01840 | G37: 7 | H37: 449172 | I37: 0379338430 | J37: T032022221100139609 | L37: Nguyễn Bá Lạp | M37: 1601184706 | N37: =IF(COUNTIF($B$2:B37,B37)=1,1,0) -> 1 | O37: PE1800 | P37: 1601184706 | Q37: PB15040053029 | R37: PB15040053029 | S37: Nguyễn Thị MInh | T37: Nguyễn Thị MInh | U37: Ấp Phước Hiệp, Phường Tân Hải, Thành phố Hồ Chí Minh | V37: Ấp Phước Hiệp, Phường Tân Hải, Thành phố Hồ Chí Minh | W37: 0 | X37: CNVC | Y37: 2026 | Z37: 7 | AA37: 1 | AB37: 415900 | AC37: 33272 | AD37: 0 | AE37: 0 | AF37: DT | AG37: 03 | AH37: B1D0239ZA | AI37: 01D | AJ37: 0 | AK37: 001840 | AL37: 0 | AM37: 0 | AN37: 0 | AO37: 0 | AP37: NH | AQ37: 0 | AR37: 0 | AS37: 02/08/26 | AT37: 1847266 | AU37: K26TDA | AV37: 0 | AW37: 29969 | AX37: 0379338430 | AY37: T032022221100139609 | AZ37: 1-7/2026 | BA37: 449172 | BB37: CON NO | BC37: =RIGHT(AK37,5) -> 01840 | BD37: =AI37&"-"&BC37 -> 01D-01840
A38: =SUBTOTAL(103,$L$2:L38) -> 37 | B38: PB15040036916 | C38: Lê Tấn Hoàng | D38: Ấp Phước Hiệp, Phường Tân Hải, Thành phố Hồ Chí Minh, Việt Nam | E38: B1D0238ZA | F38: 01D-08200 | G38: 7 | H38: 459454 | I38: 0903880195 | J38: T032022221100133546 | L38: Nguyễn Bá Lạp | M38: 1601181709 | N38: =IF(COUNTIF($B$2:B38,B38)=1,1,0) -> 1 | O38: PE1800 | P38: 1601181709 | Q38: PB15040036916 | R38: PB15040036916 | S38: Lê Tấn Hoàng | T38: Lê Tấn Hoàng | U38: Ấp Phước Hiệp, Phường Tân Hải, Thành phố Hồ Chí Minh, Việt Nam | V38: Ấp Phước Hiệp, Phường Tân Hải, Thành phố Hồ Chí Minh, Việt Nam | W38: 0 | X38: KHBT | Y38: 2026 | Z38: 7 | AA38: 1 | AB38: 425420 | AC38: 34034 | AD38: 0 | AE38: 0 | AF38: DT | AG38: 01 | AH38: B1D0238ZA | AI38: 01D | AJ38: 0 | AK38: 008200 | AL38: 0 | AM38: 0 | AN38: 0 | AO38: 0 | AP38: NH | AQ38: 0 | AR38: 0 | AS38: 02/08/26 | AT38: 1847049 | AU38: K26TDA | AV38: 0 | AW38: 29257 | AX38: 0903880195 | AY38: T032022221100133546 | AZ38: 1-7/2026 | BA38: 459454 | BB38: CON NO | BC38: =RIGHT(AK38,5) -> 08200 | BD38: =AI38&"-"&BC38 -> 01D-08200
A39: =SUBTOTAL(103,$L$2:L39) -> 38 | B39: PB15040002384 | C39: Nguyễn Văn Sửu | D39: Ấp Phước Hiệp, Phường Tân Hải, Thành phố Hồ Chí Minh, Việt Nam | E39: B1D0238ZA | F39: 01D-08730 | G39: 7 | H39: 1694822 | I39: 0906394018 | J39: T4920212120635312 | L39: Nguyễn Bá Lạp | M39: 1601181206 | N39: =IF(COUNTIF($B$2:B39,B39)=1,1,0) -> 1 | O39: PE1800 | P39: 1601181206 | Q39: PB15040002384 | R39: PB15040002384 | S39: Nguyễn Văn Sửu | T39: Nguyễn Văn Sửu | U39: Ấp Phước Hiệp, Phường Tân Hải, Thành phố Hồ Chí Minh, Việt Nam | V39: Ấp Phước Hiệp, Phường Tân Hải, Thành phố Hồ Chí Minh, Việt Nam | W39: 0 | X39: KHBT | Y39: 2026 | Z39: 7 | AA39: 1 | AB39: 1569280 | AC39: 125542 | AD39: 0 | AE39: 0 | AF39: DT | AG39: 01 | AH39: B1D0238ZA | AI39: 01D | AJ39: 0 | AK39: 008730 | AL39: 0 | AM39: 0 | AN39: 0 | AO39: 0 | AP39: NH | AQ39: 0 | AR39: 0 | AS39: 02/08/26 | AT39: 1847074 | AU39: K26TDA | AV39: 0 | AW39: 29148 | AX39: 0906394018 | AY39: T4920212120635312 | AZ39: 1-7/2026 | BA39: 1694822 | BB39: CON NO | BC39: =RIGHT(AK39,5) -> 08730 | BD39: =AI39&"-"&BC39 -> 01D-08730
A40: =SUBTOTAL(103,$L$2:L40) -> 39 | B40: PB15040041918 | C40: Mai Văn Công | D40: Ấp Phước Hiệp, Phường Tân Hải, Thành phố Hồ Chí Minh, Việt Nam | E40: B1D0238ZA | F40: 01D-09070 | G40: 7 | H40: 788946 | I40: 0379485020 | J40: T032022221100139860 | L40: Nguyễn Bá Lạp | M40: 1601182116 | N40: =IF(COUNTIF($B$2:B40,B40)=1,1,0) -> 1 | O40: PE1800 | P40: 1601182116 | Q40: PB15040041918 | R40: PB15040041918 | S40: Mai Văn Công | T40: Mai Văn Công | U40: Ấp Phước Hiệp, Phường Tân Hải, Thành phố Hồ Chí Minh, Việt Nam | V40: Ấp Phước Hiệp, Phường Tân Hải, Thành phố Hồ Chí Minh, Việt Nam | W40: 0 | X40: KHBT | Y40: 2026 | Z40: 7 | AA40: 1 | AB40: 730506 | AC40: 58440 | AD40: 0 | AE40: 0 | AF40: DT | AG40: 01 | AH40: B1D0238ZA | AI40: 01D | AJ40: 0 | AK40: 009070 | AL40: 0 | AM40: 0 | AN40: 0 | AO40: 0 | AP40: NH | AQ40: 0 | AR40: 0 | AS40: 02/08/26 | AT40: 1847121 | AU40: K26TDA | AV40: 0 | AW40: 29363 | AX40: 0379485020 | AY40: T032022221100139860 | AZ40: 1-7/2026 | BA40: 788946 | BB40: CON NO | BC40: =RIGHT(AK40,5) -> 09070 | BD40: =AI40&"-"&BC40 -> 01D-09070
...

Sheet Sheet2
A1: BẢNG TỔNG HỢP TỒN NỢ
B2: Nhóm | C2: 16h ngày 20/08/2026 | F2: 16h ngày 20/08/2026
A3: STT | C3: Hoá Đơn | D3: Khách Hàng | E3: Tiền Nợ | F3: Hoá Đơn | G3: Khách Hàng | H3: Tiền Nợ
A4: 1 | B4: Bùi Thanh Dũng | C4: =COUNTIFS(Sheet1!$L:$L,$B4,Sheet1!$F:$F,"<>") -> 185 | D4: =SUMIFS(Sheet1!$N$2:$N$39836,Sheet1!$L$2:$L$39836,$B4,Sheet1!$N$2:$N$39836,1) -> 181 | E4: =SUMIF(Sheet1!$L:$L,$B4,Sheet1!$H:$H) -> 252869193
A5: 2 | B5: Đào Sơn Hà | C5: =COUNTIFS(Sheet1!$L:$L,$B5,Sheet1!$F:$F,"<>") -> 112 | D5: =SUMIFS(Sheet1!$N$2:$N$39836,Sheet1!$L$2:$L$39836,$B5,Sheet1!$N$2:$N$39836,1) -> 112 | E5: =SUMIF(Sheet1!$L:$L,$B5,Sheet1!$H:$H) -> 110927376
A6: 3 | B6: Đỗ Hiếu Lễ | C6: =COUNTIFS(Sheet1!$L:$L,$B6,Sheet1!$F:$F,"<>") -> 233 | D6: =SUMIFS(Sheet1!$N$2:$N$39836,Sheet1!$L$2:$L$39836,$B6,Sheet1!$N$2:$N$39836,1) -> 231 | E6: =SUMIF(Sheet1!$L:$L,$B6,Sheet1!$H:$H) -> 159014290
A7: 4 | B7: Đỗ Thị Diễm Trang | C7: =COUNTIFS(Sheet1!$L:$L,$B7,Sheet1!$F:$F,"<>") -> 336 | D7: =SUMIFS(Sheet1!$N$2:$N$39836,Sheet1!$L$2:$L$39836,$B7,Sheet1!$N$2:$N$39836,1) -> 323 | E7: =SUMIF(Sheet1!$L:$L,$B7,Sheet1!$H:$H) -> 312100597
A8: 5 | B8: Huỳnh Tấn Phát | C8: =COUNTIFS(Sheet1!$L:$L,$B8,Sheet1!$F:$F,"<>") -> 451 | D8: =SUMIFS(Sheet1!$N$2:$N$39836,Sheet1!$L$2:$L$39836,$B8,Sheet1!$N$2:$N$39836,1) -> 440 | E8: =SUMIF(Sheet1!$L:$L,$B8,Sheet1!$H:$H) -> 286792762
A9: 6 | B9: Nguyễn Bá Lạp | C9: =COUNTIFS(Sheet1!$L:$L,$B9,Sheet1!$F:$F,"<>") -> 181 | D9: =SUMIFS(Sheet1!$N$2:$N$39836,Sheet1!$L$2:$L$39836,$B9,Sheet1!$N$2:$N$39836,1) -> 180 | E9: =SUMIF(Sheet1!$L:$L,$B9,Sheet1!$H:$H) -> 135152136
A10: 7 | B10: Nguyễn Ngọc Kỳ | C10: =COUNTIFS(Sheet1!$L:$L,$B10,Sheet1!$F:$F,"<>") -> 362 | D10: =SUMIFS(Sheet1!$N$2:$N$39836,Sheet1!$L$2:$L$39836,$B10,Sheet1!$N$2:$N$39836,1) -> 352 | E10: =SUMIF(Sheet1!$L:$L,$B10,Sheet1!$H:$H) -> 302447477
A11: 8 | B11: Phạm Trần thanh Tâm | C11: =COUNTIFS(Sheet1!$L:$L,$B11,Sheet1!$F:$F,"<>") -> 1004 | D11: =SUMIFS(Sheet1!$N$2:$N$39836,Sheet1!$L$2:$L$39836,$B11,Sheet1!$N$2:$N$39836,1) -> 551 | E11: =SUMIF(Sheet1!$L:$L,$B11,Sheet1!$H:$H) -> 2809476055

Sheet Sheet2 (2)
A1: BẢNG TỔNG HỢP TỒN NỢ
B2: Nhóm | C2: 16h ngày 20/08/2026 | F2: 16h ngày 20/08/2026 | I2: Khách Hàng đã thanh toán
A3: STT | C3: Hoá Đơn | D3: Khách Hàng | E3: Tiền Nợ | F3: Hoá Đơn | G3: Khách Hàng | H3: Tiền Nợ
A4: 1 | B4: Bùi Thanh Dũng | C4: =COUNTIFS(Sheet1!$L:$L,$B4,Sheet1!$F:$F,"<>") -> 185 | D4: =SUMIFS(Sheet1!$N$2:$N$39836,Sheet1!$L$2:$L$39836,$B4,Sheet1!$N$2:$N$39836,1) -> 181 | E4: =SUMIF(Sheet1!$L:$L,$B4,Sheet1!$H:$H) -> 252869193
A5: 2 | B5: Đào Sơn Hà | C5: =COUNTIFS(Sheet1!$L:$L,$B5,Sheet1!$F:$F,"<>") -> 112 | D5: =SUMIFS(Sheet1!$N$2:$N$39836,Sheet1!$L$2:$L$39836,$B5,Sheet1!$N$2:$N$39836,1) -> 112 | E5: =SUMIF(Sheet1!$L:$L,$B5,Sheet1!$H:$H) -> 110927376
A6: 3 | B6: Đỗ Hiếu Lễ | C6: =COUNTIFS(Sheet1!$L:$L,$B6,Sheet1!$F:$F,"<>") -> 233 | D6: =SUMIFS(Sheet1!$N$2:$N$39836,Sheet1!$L$2:$L$39836,$B6,Sheet1!$N$2:$N$39836,1) -> 231 | E6: =SUMIF(Sheet1!$L:$L,$B6,Sheet1!$H:$H) -> 159014290
A7: 4 | B7: Đỗ Thị Diễm Trang | C7: =COUNTIFS(Sheet1!$L:$L,$B7,Sheet1!$F:$F,"<>") -> 336 | D7: =SUMIFS(Sheet1!$N$2:$N$39836,Sheet1!$L$2:$L$39836,$B7,Sheet1!$N$2:$N$39836,1) -> 323 | E7: =SUMIF(Sheet1!$L:$L,$B7,Sheet1!$H:$H) -> 312100597
A8: 5 | B8: Huỳnh Tấn Phát | C8: =COUNTIFS(Sheet1!$L:$L,$B8,Sheet1!$F:$F,"<>") -> 451 | D8: =SUMIFS(Sheet1!$N$2:$N$39836,Sheet1!$L$2:$L$39836,$B8,Sheet1!$N$2:$N$39836,1) -> 440 | E8: =SUMIF(Sheet1!$L:$L,$B8,Sheet1!$H:$H) -> 286792762
A9: 6 | B9: Nguyễn Bá Lạp | C9: =COUNTIFS(Sheet1!$L:$L,$B9,Sheet1!$F:$F,"<>") -> 181 | D9: =SUMIFS(Sheet1!$N$2:$N$39836,Sheet1!$L$2:$L$39836,$B9,Sheet1!$N$2:$N$39836,1) -> 180 | E9: =SUMIF(Sheet1!$L:$L,$B9,Sheet1!$H:$H) -> 135152136
A10: 7 | B10: Nguyễn Ngọc Kỳ | C10: =COUNTIFS(Sheet1!$L:$L,$B10,Sheet1!$F:$F,"<>") -> 362 | D10: =SUMIFS(Sheet1!$N$2:$N$39836,Sheet1!$L$2:$L$39836,$B10,Sheet1!$N$2:$N$39836,1) -> 352 | E10: =SUMIF(Sheet1!$L:$L,$B10,Sheet1!$H:$H) -> 302447477
A11: 8 | B11: Phạm Trần thanh Tâm | C11: =COUNTIFS(Sheet1!$L:$L,$B11,Sheet1!$F:$F,"<>") -> 1004 | D11: =SUMIFS(Sheet1!$N$2:$N$39836,Sheet1!$L$2:$L$39836,$B11,Sheet1!$N$2:$N$39836,1) -> 551 | E11: =SUMIF(Sheet1!$L:$L,$B11,Sheet1!$H:$H) -> 2809476055
